Workbook

Sheet Questionnaire
C1: Questionnaire ENNEAGRAMME
C3: Merci de reprendre chacune des affirmations ci-dessous et indiquez une note de 0 à 3 pour chaque affirmation : 0 Jamais vrai, 1 parfois vrai, 2 souvent vrai, 3 toujours vrai.
B5: 1 | C5: Je passe pour une personne solide et suscite assez rapidement le respect quand je m’affirme en société.
B6: 2 | C6: Face à des situations de tension, de conflit ou d'agressivité, je garde facilement mon calme et considère ma stabilité émotionnelle comme un atout pour prendre du recul avant de m'exprimer.
B7: 3 | C7: Si je repère des erreurs, je me sens le devoir d’intervenir rapidement pour corriger les choses car tous les détails comptent si on veut améliorer les choses pour progresser.
B9: 4 | C9: Je me sens plutôt bien quand je suis au service des autres, quitte parfois à sacrifier facilement mon temps, mon énergie ou même mon argent, pour les soutenir face à leurs difficultés.
B10: 5 | C10: J’aime mobiliser de l’énergie dans une action particulière, surtout si celle-ci contribue à mon succès et/ou à ma reconnaissance personnelle, sociale ou professionnelle
B11: 6 | C11: Enfant, je me sentais déjà très différent(e) des autres et j’avais le sentiment de déranger.
B13: 7 | C13: Je tiens particulièrement à préserver ma vie privée et avoir du temps pour moi, pour me retrouver et prendre le recul dont j’ai besoin quand c’est nécessaire.
B14: 8 | C14: Quand j’ai des décisions importantes à prendre, je demande l’avis des autres, car j’ai parfois peur de faire une bêtise.
B15: 9 | C15: Afin de préserver un maximum d’opportunités intéressantes, je peux me sentir vite frustré(e) si l’on m’impose des règles qui à mes yeux n’ont pas lieu d’être.
B17: 10 | C17: Même en cas de tension relationnelle, je sais préserver un sentiment d’union et d’harmonie, car j’estime que c’est la meilleure chose qui soit pour apaiser les esprits et préserver le lien.
B18: 11 | C18: J’aime que les choses soient parfaites et je suis dérangé(e) par les imperfections à commencer par ce que les gens peuvent percevoir chez moi.
B19: 12 | C19: Je peux consacrer facilement du temps libre pour soutenir des personnes qui en ont besoin et trouve cela gratifiant de sentir que ma présence est utile pour eux.
... B35: 24 | C35: Je peux vite me sentir anxieux(se) ou imprudent(e) si je dois prendre d’importantes décisions sans l’avis des autres.
A37: < | B37: 25 | C37: Je peux parfois faire abstraction de quelques règles importantes, si cela me permet de vivre des situations plus excitantes.
B38: 26 | C38: J’ai confiance en ma force et en mon courage, lorsqu’arrive le moment de prendre une décision, je ne fais pas de compromis.
B39: 27 | C39: Quitte à prendre sur moi, je suis capable de beaucoup de patience pour éviter les discussions houleuses, les confrontations ou les conflits
B41: 28 | C41: Je me positionne en négociateur(trice) assez ferme, car je sais imposer mes idées et reprendre le contrôle d’une situation pour en sortir gagnant.
B42: 29 | C42: Je suis perçu(e) par mon entourage comme ambitieux(se) et très mobilisé(e) pour réussir mes objectifs dès que possible.
B43: 30 | C43: J’aime me lancer dans de nouvelles aventures ou projets stimulants, même si les situations en cours ne sont pas encore vraiment terminées.
B45: 31 | C45: J’ai souvent l’impression que personne ne peut me comprendre car il m’est impossible d’expliquer mon fonctionnement et ce sentiment intense d’être différent(e).
B46: 32 | C46: Par soucis de paix d'esprit et de tranquillité, j’ai parfois tendance à me voiler la face, en laissant trainer des situations importantes à régler, pour plus tard.
B47: 33 | C47: Je préfère me tenir à l’écart, voire me retirer discrètement de l’agitation, plutôt que de me retrouver pris dans des conversations plus émotionnelles, voire superficielles.
B49: 34 | C49: J’aime tenir une place de choix dans la vie de mon entourage, savoir qu’ils peuvent compter sur moi en cas de besoin est essentiel pour mon bien-être.
B50: 35 | C50: Afin d’éviter toutes critiques négatives, je peux donner beaucoup de moi-même et obtenir facilement l’admiration des autres pour l’efficacité de mon travail.
B51: 36 | C51: Je suis facilement préoccupé(e) ou inquiet(e) par une chose ou une autre qui, pourrait nuire au bien-être de mes proches, concernant ma famille, mes équipes ou mon organisation.
B53: 37 | C53: Enfant, j’avais le sentiment d’avoir rarement été vu(e) ou entendu(e).
... B157: 115 | C157: Tendre vers l’excellence est suffisamment important pour moi pour que j’y consacre mes pensées, mon temps et mon argent le plus régulièrement possible.
A158: < | B158: 116 | C158: J’ai tendance à être attentif(ve) voire soupçonneux(se) à l’égard des propositions qui pourraient davantage privilégier les bénéfices individuels que collectifs.
A159: T ** | B159: 117 | C159: J’aime ce qui est familier, la routine me convient pour autant qu’elle soit confortable et qu’elle préserve ma stabilité, voire ma tranquillité émotionnelle et mentale.
B161: 118 | C161: Je suis de nature plutôt méfiant(e), je sens très vite si un danger ou une situation menaçante pourrait se présenter en terme de non respect de l’éthique.
B162: 119 | C162: Quand différents points de vue me semblent intéressants, j’ai du mal à me donner des priorités et à m’engager rapidement sur des décisions précises, car justement, tous les points de vue sont intéressants.
B163: 120 | C163: Même si j’ai parfois des baisses d’énergie (remise en cause, déception, pression), je peux montrer facilement aux autres que je reste mobilisé(e) et confiant(e) pour avancer vers l’atteinte de mes ou nos objectifs.
B165: 121 | C165: Je peux facilement avoir tendance à la nostalgie en ravivant des sentiments du passé pour donner plus d’intensité ma vie présente.
B166: 122 | C166: Enfant, je me préoccupais déjà plus de mes propres sources de stimulation que des problèmes des autres.
B167: 123 | C167: Je peux être critique avec les autres s’ils m’apparaissent imprécis, inefficaces ou qu’ils n’avancent pas dans le cadre de la direction attendue.
B169: 124 | C169: J’ai une tendance naturelle à cloisonner un peu ma vie (travail, famille, sports, loisirs,..), les personnes de ces différents domaines ne se connaissent pas entre-elles.
B170: 125 | C170: Le courage et la force sont des atouts que je mobilise facilement, quand il s’agit de reprendre la main sur des situations qui ne me conviennent pas.
B171: 126 | C171: Enfant, il était plus important pour moi de satisfaire les besoins des autres et de leur venir en aide.
...

Sheet résultat
C2: A | F2: B | I2: C | L2: D | O2: E | R2: F | U2: G | X2: H | AA2: I
B4: 1 | C4: =Questionnaire!D5 -> 0 | E4: 2 | F4: =Questionnaire!D6 -> 0 | H4: 3 | I4: =Questionnaire!D7 -> 0 | K4: 4 | L4: =Questionnaire!D9 -> 0 | N4: 5 | O4: =Questionnaire!D10 -> 0 | Q4: 6 | R4: =Questionnaire!D11 -> 0 | T4: 7 | U4: =Questionnaire!D13 -> 0 | W4: 8 | X4: =Questionnaire!D14 -> 0 | Z4: 9 | AA4: =Questionnaire!D15 -> 0
B5: 18 | C5: =Questionnaire!D27 -> 0 | E5: 10 | F5: =Questionnaire!D17 -> 0 | H5: 11 | I5: =Questionnaire!D18 -> 0 | K5: 12 | L5: =Questionnaire!D19 -> 0 | N5: 13 | O5: =Questionnaire!D21 -> 0 | Q5: 14 | R5: =Questionnaire!D22 -> 0 | T5: 15 | U5: =Questionnaire!D23 -> 0 | W5: 16 | X5: =Questionnaire!D25 -> 0 | Z5: 17 | AA5: =Questionnaire!D26 -> 0
B6: 26 | C6: =Questionnaire!D38 -> 0 | E6: 27 | F6: =Questionnaire!D39 -> 0 | H6: 19 | I6: =Questionnaire!D29 -> 0 | K6: 20 | L6: =Questionnaire!D30 -> 0 | N6: 21 | O6: =Questionnaire!D31 -> 0 | Q6: 22 | R6: =Questionnaire!D33 -> 0 | T6: 23 | U6: =Questionnaire!D34 -> 0 | W6: 24 | X6: =Questionnaire!D35 -> 0 | Z6: 25 | AA6: =Questionnaire!D37 -> 0
B8: 28 | C8: =Questionnaire!D41 -> 0 | E8: 32 | F8: =Questionnaire!D46 -> 0 | H8: 35 | I8: =Questionnaire!D50 -> 0 | K8: 34 | L8: =Questionnaire!D49 -> 0 | N8: 29 | O8: =Questionnaire!D42 -> 0 | Q8: 31 | R8: =Questionnaire!D45 -> 0 | T8: 33 | U8: =Questionnaire!D47 -> 0 | W8: 36 | X8: =Questionnaire!D51 -> 0 | Z8: 30 | AA8: =Questionnaire!D43 -> 0
B9: 45 | C9: =Questionnaire!D63 -> 0 | E9: 37 | F9: =Questionnaire!D53 -> 0 | H9: 41 | I9: =Questionnaire!D58 -> 0 | K9: 42 | L9: =Questionnaire!D59 -> 0 | N9: 43 | O9: =Questionnaire!D61 -> 0 | Q9: 38 | R9: =Questionnaire!D54 -> 0 | T9: 39 | U9: =Questionnaire!D55 -> 0 | W9: 40 | X9: =Questionnaire!D57 -> 0 | Y9: 0 | Z9: 44 | AA9: =Questionnaire!D62 -> 0
B10: 49 | C10: =Questionnaire!D69 -> 0 | E10: 54 | F10: =Questionnaire!D75 -> 0 | H10: 46 | I10: =Questionnaire!D65 -> 0 | K10: 47 | L10: =Questionnaire!D66 -> 0 | N10: 51 | O10: =Questionnaire!D71 -> 0 | Q10: 52 | R10: =Questionnaire!D73 -> 0 | T10: 53 | U10: =Questionnaire!D74 -> 0 | W10: 48 | X10: =Questionnaire!D67 -> 0 | Z10: 50 | AA10: =Questionnaire!D70 -> 0
B12: 60 | C12: =Questionnaire!D83 -> 0 | E12: 62 | F12: =Questionnaire!D86 -> 0 | H12: 57 | I12: =Questionnaire!D79 -> 0 | K12: 61 | L12: =Questionnaire!D85 -> 0 | N12: 56 | O12: =Questionnaire!D78 -> 0 | Q12: 58 | R12: =Questionnaire!D81 -> 0 | T12: 55 | U12: =Questionnaire!D77 -> 0 | W12: 59 | X12: =Questionnaire!D82 -> 0 | Z12: 63 | AA12: =Questionnaire!D87 -> 0
B13: 64 | C13: =Questionnaire!D89 -> 0 | E13: 68 | F13: =Questionnaire!D94 -> 0 | H13: 71 | I13: =Questionnaire!D98 -> 0 | K13: 69 | L13: =Questionnaire!D95 -> 0 | N13: 70 | O13: =Questionnaire!D97 -> 0 | Q13: 65 | R13: =Questionnaire!D90 -> 0 | T13: 72 | U13: =Questionnaire!D99 -> 0 | W13: 66 | X13: =Questionnaire!D91 -> 0 | Z13: 67 | AA13: =Questionnaire!D93 -> 0
B14: 80 | C14: =Questionnaire!D110 -> 0 | E14: 75 | F14: =Questionnaire!D103 -> 0 | H14: 77 | I14: =Questionnaire!D106 -> 0 | K14: 73 | L14: =Questionnaire!D101 -> 0 | N14: 78 | O14: =Questionnaire!D107 -> 0 | Q14: 79 | R14: =Questionnaire!D109 -> 0 | T14: 76 | U14: =Questionnaire!D105 -> 0 | W14: 81 | X14: =Questionnaire!D111 -> 0 | Z14: 74 | AA14: =Questionnaire!D102 -> 0
B16: 87 | C16: =Questionnaire!D119 -> 0 | E16: 90 | F16: =Questionnaire!D123 -> 0 | H16: 82 | I16: =Questionnaire!D113 -> 0 | K16: 85 | L16: =Questionnaire!D117 -> 0 | N16: 88 | O16: =Questionnaire!D121 -> 0 | Q16: 83 | R16: =Questionnaire!D114 -> 0 | T16: 86 | U16: =Questionnaire!D118 -> 0 | W16: 89 | X16: =Questionnaire!D122 -> 0 | Z16: 84 | AA16: =Questionnaire!D115 -> 0
B17: 98 | C17: =Questionnaire!D134 -> 0 | E17: 92 | F17: =Questionnaire!D126 -> 0 | H17: 96 | I17: =Questionnaire!D131 -> 0 | K17: 99 | L17: =Questionnaire!D135 -> 0 | N17: 93 | O17: =Questionnaire!D127 -> 0 | Q17: 94 | R17: =Questionnaire!D129 -> 0 | T17: 97 | U17: =Questionnaire!D133 -> 0 | W17: 91 | X17: =Questionnaire!D125 -> 0 | Z17: 95 | AA17: =Questionnaire!D130 -> 0
B18: 101 | C18: =Questionnaire!D138 -> 0 | E18: 102 | F18: =Questionnaire!D139 -> 0 | H18: 100 | I18: =Questionnaire!D137 -> 0 | K18: 103 | L18: =Questionnaire!D141 -> 0 | N18: 105 | O18: =Questionnaire!D143 -> 0 | Q18: 104 | R18: =Questionnaire!D142 -> 0 | T18: 106 | U18: =Questionnaire!D145 -> 0 | W18: 108 | X18: =Questionnaire!D147 -> 0 | Z18: 107 | AA18: =Questionnaire!D146 -> 0
B20: 114 | C20: =Questionnaire!D155 -> 0 | E20: 117 | F20: =Questionnaire!D159 -> 0 | H20: 109 | I20: =Questionnaire!D149 -> 0 | K20: 112 | L20: =Questionnaire!D153 -> 0 | N20: 115 | O20: =Questionnaire!D157 -> 0 | Q20: 110 | R20: =Questionnaire!D150 -> 0 | T20: 113 | U20: =Questionnaire!D154 -> 0 | W20: 116 | X20: =Questionnaire!D158 -> 0 | Z20: 111 | AA20: =Questionnaire!D151 -> 0
B21: 125 | C21: =Questionnaire!D170 -> 0 | E21: 119 | F21: =Questionnaire!D162 -> 0 | H21: 123 | I21: =Questionnaire!D167 -> 0 | K21: 126 | L21: =Questionnaire!D171 -> 0 | N21: 120 | O21: =Questionnaire!D163 -> 0 | Q21: 121 | R21: =Questionnaire!D165 -> 0 | T21: 124 | U21: =Questionnaire!D169 -> 0 | W21: 118 | X21: =Questionnaire!D161 -> 0 | Z21: 122 | AA21: =Questionnaire!D166 -> 0
B22: 128 | C22: =Questionnaire!D174 -> 0 | E22: 129 | F22: =Questionnaire!D175 -> 0 | H22: 127 | I22: =Questionnaire!D173 -> 0 | K22: 130 | L22: =Questionnaire!D177 -> 0 | N22: 132 | O22: =Questionnaire!D179 -> 0 | Q22: 131 | R22: =Questionnaire!D178 -> 0 | T22: 133 | U22: =Questionnaire!D181 -> 0 | W22: 135 | X22: =Questionnaire!D183 -> 0 | Z22: 134 | AA22: =Questionnaire!D182 -> 0 | AC22: Profil
B25: 8 | C25: =SUM(C4:C22) -> 0 | E25: 9 | F25: =SUM(F4:F22) -> 0 | H25: 1 | I25: =SUM(I4:I22) -> 0 | K25: 2 | L25: =SUM(L4:L22) -> 0 | N25: 3 | O25: =SUM(O4:O22) -> 0 | Q25: 4 | R25: =SUM(R4:R22) -> 0 | T25: 5 | U25: =SUM(U4:U22) -> 0 | W25: 6 | X25: =SUM(X4:X22) -> 0 | Z25: 7 | AA25: =SUM(AA4:AA22) -> 0
AC26: 9- Médiateur | AD26: =AE26/$AE$37 -> #DIV/0! | AE26: =F25 -> 0
AC27: 1- Perfectionniste | AD27: =AE27/$AE$37 -> #DIV/0! | AE27: =I25 -> 0
AC28: 2- Aidant | AD28: =AE28/$AE$37 -> #DIV/0! | AE28: =L25 -> 0
AC29: 3- Compétiteur | AD29: =AE29/$AE$37 -> #DIV/0! | AE29: =O25 -> 0
AC30: 4- Artiste | AD30: =AE30/$AE$37 -> #DIV/0! | AE30: =R25 -> 0
AC31: 5- Penseur | AD31: =AE31/$AE$37 -> #DIV/0! | AE31: =U25 -> 0
AC32: 6- Loyaliste | AD32: =AE32/$AE$37 -> #DIV/0! | AE32: =X25 -> 0
AC33: 7- Jouisseur | AD33: =AE33/$AE$37 -> #DIV/0! | AE33: =AA25 -> 0
AC34: 8- Leader | AD34: =AE34/$AE$37 -> #DIV/0! | AE34: =C25 -> 0
AD37: =SUM(AD26:AD34) -> #DIV/0! | AE37: =SUM(AE26:AE34) -> 0
